terminate called after throwing an instance of 'std::runtime_error'
  what():  dettrace runtime exception: Deadlock detected!

